============================= test session starts ==============================
platform linux -- Python 3.12.1, pytest-8.2.1, pluggy-1.6.0 -- /home/codespace/.python/current/bin/python3
cachedir: .pytest_cache
hypothesis profile 'default' -> database=DirectoryBasedExampleDatabase(PosixPath('/workspaces/ZoloHQ/.hypothesis/examples'))
Using --randomly-seed=383326089
rootdir: /workspaces/ZoloHQ
configfile: pytest.ini
plugins: anyio-4.9.0, hypothesis-6.103.1, cov-5.0.0, timeout-2.3.1, asyncio-0.23.6, randomly-3.15.0
asyncio: mode=Mode.STRICT
collecting ... collected 0 items / 1 error

==================================== ERRORS ====================================
___________________ ERROR collecting test_api_integration.py ___________________
ImportError while importing test module '/workspaces/ZoloHQ/test_api_integration.py'.
Hint: make sure your test modules/packages have valid Python names.
Traceback:
/home/codespace/.python/current/lib/python3.12/importlib/__init__.py:90: in import_module
    return _bootstrap._gcd_import(name[level:], package, level)
test_api_integration.py:16: in <module>
    import requests
/home/codespace/.python/current/lib/python3.12/site-packages/requests/__init__.py:43: in <module>
    import urllib3
/home/codespace/.python/current/lib/python3.12/site-packages/urllib3/__init__.py:8: in <module>
    from .connectionpool import (
/home/codespace/.python/current/lib/python3.12/site-packages/urllib3/connectionpool.py:11: in <module>
    from .exceptions import (
/home/codespace/.python/current/lib/python3.12/site-packages/urllib3/exceptions.py:2: in <module>
    from .packages.six.moves.http_client import (
E   ModuleNotFoundError: No module named 'urllib3.packages.six.moves'
=========================== short test summary info ============================
ERROR test_api_integration.py
!!!!!!!!!!!!!!!!!!!! Interrupted: 1 error during collection !!!!!!!!!!!!!!!!!!!!
=============================== 1 error in 1.26s ===============================
