============================= test session starts ==============================
platform linux -- Python 3.12.1, pytest-8.2.1, pluggy-1.6.0 -- /home/codespace/.python/current/bin/python3
cachedir: .pytest_cache
hypothesis profile 'default' -> database=DirectoryBasedExampleDatabase(PosixPath('/workspaces/ZoloHQ/.hypothesis/examples'))
Using --randomly-seed=1076035081
rootdir: /workspaces/ZoloHQ
configfile: pytest.ini
plugins: anyio-4.9.0, hypothesis-6.103.1, cov-5.0.0, timeout-2.3.1, asyncio-0.23.6, randomly-3.15.0
asyncio: mode=Mode.STRICT
collecting ... collected 3 items

test_real_data_connection.py::test_bybit_connector FAILED                [ 33%]
test_real_data_connection.py::test_environment_config PASSED             [ 66%]
test_real_data_connection.py::test_production_data_manager PASSED        [100%]

=================================== FAILURES ===================================
_____________________________ test_bybit_connector _____________________________
test_real_data_connection.py:64: in test_bybit_connector
    from data.execution.bybit_connector import BybitConnector
E   ModuleNotFoundError: No module named 'data.execution'

During handling of the above exception, another exception occurred:
test_real_data_connection.py:111: in test_bybit_connector
    raise AssertionError()
E   AssertionError
----------------------------- Captured stdout call -----------------------------

üîç Testing Bybit Connector...
--------------------------------------------------
‚ùå Connector test failed: No module named 'data.execution'
------------------------------ Captured log call -------------------------------
ERROR    test_real_data_connection:test_real_data_connection.py:110 Full error details:
Traceback (most recent call last):
  File "/workspaces/ZoloHQ/test_real_data_connection.py", line 64, in test_bybit_connector
    from data.execution.bybit_connector import BybitConnector
ModuleNotFoundError: No module named 'data.execution'
=========================== short test summary info ============================
FAILED test_real_data_connection.py::test_bybit_connector - AssertionError
========================= 1 failed, 2 passed in 0.35s ==========================
